Workbook

Sheet LEEME
A1: Always Up: CRM y plan de captación
A2: Actualizado el 13/10/2026. Primero esta página (2 minutos), luego la pestaña Calendario diario.
A4: TU RUTINA
A5: Cada mañana (15 min) | B5: Abre Calendario diario. Hoy sale en amarillo. Haz lo que diga, marca Hecho. Revisa bandeja, Instagram y WhatsApp.
A6: La víspera (20 min) | B6: Prepara los correos del día siguiente. Si tu correo permite programar, déjalos programados. Si no, los envías a mano a las 07:30 de Nueva York. El calendario te dice cuáles y de dónde copiar el texto.
A7: Cada viernes (20 min) | B7: Revisión semanal: cuéntame respuestas, rebotes y llamadas. Yo actualizo el plan y preparo la siguiente tanda.
A8: Cada lunes (5 min) | B8: Escríbeme «investiga 10 clubes más». Yo verifico contactos y dejo los correos listos.
A9: PESTAÑAS
A10: Calendario diario | B10: Tu lista de tareas por día, con hora, pasos y dónde está el texto. Es lo único que necesitas mirar a diario.
A11: Textos para copiar | B11: Todos los correos, notas de LinkedIn y mensajes, listos para pegar. Incluye respuestas tipo para cuando contesten.
A12: Hoy | B12: Panel con números (se calculan solos desde las pestañas de segmento).
A13: Plan por servicio | B13: Cómo conseguimos clientes en cada servicio y en qué orden.
A14: Verificación | B14: De dónde sale cada email y qué tan fiable es.
A15: Segmento A / B / C | B15: Las listas de clubes (A), universidades y clubes de América (B) y leads de becas (C). Actualiza Estado y Fecha de último contacto.
A16: Dashboard, LinkedIn, Oportunidades | B16: Fotos del embudo, registro de LinkedIn y notas sueltas.
A17: COMO Y CUANDO ENVIAR
A18: Qué se ha comprobado (14/10/2026) | B18: El envío programado con Mail de Apple SÍ sale: llegó con Mail abierto, con Mail cerrado y con el Mac en reposo. Puede retrasarse unos 10 minutos y no avisa. Los correos programados del 14/10 sí salieron (Holbeach, 04:41).
A19: Por qué parecía que no salían | B19: El correo enviado se guarda en carpetas distintas según el programa: 'Sent' (Outlook), 'INBOX.Sent' (servidor) y 'Sent Messages' (Mail). No lo ves donde miras. Para comprobar: Outlook > buscador > escribe el destinatario > All folders.
A20: Cómo se programa | B20: Mail: correo nuevo, pega todo, flecha junto a Enviar > Enviar más tarde > fecha y hora de la columna 'Programar para (NY)'. Se programa la víspera por la tarde.
A21: Regla para no duplicar | B21: Una vez programado un correo, no lo envíes a mano. A las 08:00 busca al destinatario en todas las carpetas: si aparece, marca Hecho; solo si no aparece, lo envías a mano.
A22: Control | B22: La fuente de verdad es esta hoja: columna 'Hecho (fecha real)' de 'Textos para copiar' y el CRM. No dependas de la carpeta Enviados de ningún programa.
A23: Truco opcional | B23: Pon tu Gmail personal en copia oculta (CCO) de cada correo a un club: recibirás una copia como prueba de que salió, y verás en Gmail si entra en bandeja. El club no lo ve.
A24: TUS FRANJAS DE LLAMADA
A25: Lo que tienes en Calendly (hora Nueva York) | B25: Dom 12:00 a 17:00 | Lun 17:30 a 21:00 | Mar 13:00 a 19:00 | Mié 11:00 a 12:30 | Jue 17:00 a 21:00 | Vie 14:00 a 18:00 | Sáb no disponible.
A26: Clubes de Europa (+5 h en UK e Irlanda, +6 h en Noruega, Francia y Países Bajos; +4 y +5 del 25 al 31/10) | B26: Sirven: Martes 13:00 a 15:00 (18:00 a 20:00 en UK, buen horario para comités de voluntarios) y Miércoles 11:00 a 12:30 (16:00 a 17:30 en UK). Mal: Lunes y Jueves por la tarde (ya es de madrugada allí), Viernes (noche) y Domingo (tarde de domingo).
A27: Familias de América (México, Latinoamérica, EEUU) | B27: Sirven: Lunes y Jueves por la tarde y Martes 17:00 a 19:00.
A28: Calendly: no hace falta tocarlo | B28: Calendly enseña a cada persona los huecos en SU hora, y elige ella. Para familias de becas sirve tal cual. Para clubes, lo normal es proponer tú dos horarios concretos de esta tabla en el email de respuesta (más cómodo para ellos y sin herramienta). El enlace queda como alternativa.
A29: REGLAS QUE NO SE ROMPEN
A30: Nunca | B30: Adjuntos en el primer correo. Nombrar al partner de becas. Prometer becas o fichajes. Inventar urgencia. Discutir precio por escrito sin tu decisión.
A31: Si contestan | B31: Paras la cadencia de ese club y abres 'Respuestas tipo' (hoja Textos para copiar). Menos de 4 horas de respuesta en horario del club.
A32: Si un correo rebota | B32: Me lo dices; busco otra dirección del club y te la dejo preparada.
A33: Colores | B33: Azul claro = email 1, amarillo = follow-up 1, naranja = follow-up 2, gris = cierre, lila = LinkedIn o redes, rojo = pendiente atrasado.

Sheet Calendario diario
A1: Calendario diario: 13 de octubre a 13 de noviembre de 2026
A2: Qué haces tú cada día, a qué hora y cómo. Las horas son de Nueva York. Los correos se programan la víspera en Apple Mail (Enviar más tarde) para las 09:30 de cada club; a las 08:00 compruebas que salieron. Cambia la columna Estado a Hecho al terminar. Hoy se marca en amarillo. Si algo queda Pendiente de un día anterior, sale en rojo.
A4: Fecha | B4: Día | C4: Hora (NY) | D4: Servicio | E4: Tarea | F4: Cómo se hace, paso a paso | G4: Dónde está el texto | H4: Min | I4: Estado | J4: Notas / resultado
A5: SEMANA 12/10 a 18/10
A6: 46308 | B6: Martes | C6: 8:00 | D6: Todos | E6: Revisión diaria: bandeja, Instagram, WhatsApp | F6: 1) Outlook: mira Recibidos y busca rebotes (correos del sistema que dicen 'Undeliverable' o 'permanent fatal errors'). 2) Instagram y WhatsApp: responde a todo lo que haya entrado, máximo 12 h de espera. 3) Si un club ha contestado: para su cadencia y usa 'Respuestas tipo' en la hoja Textos para copiar. | G6: Textos para copiar (final de la hoja) | H6: 15 | I6: Hecho
A7: 46308 | B7: Martes | C7: Tarde | D7: Becas | E7: Omar: anotado el follow-up enviado hoy | F7: Nada que hacer. Si responde, pásame su mensaje. Si no, el 20/10 envías el último mensaje (ver ese día). | G7: Segmento C - Becas, fila Omar | I7: Hecho
A8: 46308 | B8: Martes | C8: 21:00 | D8: Transversal | E8: Prueba de entregabilidad (por qué tus correos caen en spam) | F8: 1) Desde joel.martinez@alwaysup.es manda a tu Gmail personal un correo con texto normal (pega el de Holbeach) y asunto normal. 2) Ábrelo en Gmail > tres puntos > Mostrar original: copia lo que ponga en SPF, DKIM y DMARC (deben decir PASS). 3) Entra en mail-tester.com, copia la dirección que te da, mándale desde alwaysup.es el mismo texto y pulsa 'Then check your score'. Pásame la nota y el resultado de SPF, DKIM y DMARC. No pegues nada más. | G8: Chat con Claude | H8: 15 | I8: Hecho
A9: 46309 | B9: Miércoles | C9: 03:30 | D9: Team/Coach | E9: ENVIAR email 1 a Søreide IL | F9: Sale a las 03:30 hora Nueva York (09:30 allí) si lo programaste la víspera. No hace falta hacer nada a esta hora. Si es follow-up, se envía respondiendo al correo original (búscalo por destinatario en Outlook o Mail y pulsa Responder). | G9: Textos para copiar | I9: Pendiente
A10: 46309 | B10: Miércoles | C10: 04:30 | D10: Team/Coach | E10: ENVIAR email 1 a Holbeach United | F10: Sale a las 04:30 hora Nueva York (09:30 allí) si lo programaste la víspera. No hace falta hacer nada a esta hora. Si es follow-up, se envía respondiendo al correo original (búscalo por destinatario en Outlook o Mail y pulsa Responder). | G10: Textos para copiar | I10: Pendiente
A11: 46309 | B11: Miércoles | C11: 8:00 | D11: Todos | E11: Revisión diaria: bandeja, Instagram, WhatsApp | F11: 1) Outlook: mira Recibidos y busca rebotes (correos del sistema que dicen 'Undeliverable' o 'permanent fatal errors'). 2) Instagram y WhatsApp: responde a todo lo que haya entrado, máximo 12 h de espera. 3) Si un club ha contestado: para su cadencia y usa 'Respuestas tipo' en la hoja Textos para copiar. | G11: Textos para copiar (final de la hoja) | H11: 15 | I11: Hecho
A12: 46309 | B12: Miércoles | C12: 8:00 | D12: Team/Coach | E12: Confirmar que salieron los correos de hoy y mirar rebotes | F12: Para cada correo: en Outlook, buscador > escribe el destinatario > 'All folders' (el correo puede estar en 'INBOX.Sent' o 'Sent Messages', no solo en 'Sent'); o en Mail, mira el buzón Enviados. Si aparece: marca Hecho en 'Textos para copiar'. Si NO aparece: envíalo ya a mano. Después mira Recibidos por si hay rebote ('Undeliverable' o 'permanent fatal errors'); si lo hay, anótalo y avísame. | G12: Outlook buscador / Mail Enviados | H12: 10 | I12: Pendiente
A13: 46309 | B13: Miércoles | C13: Libre | D13: Team/Coach | E13: Comprobar si Søreide y Holbeach recibieron el correo una o dos veces | F13: En Outlook: buscador > 'fotball@soreideil.no' y luego 'callum@holbeachunitedacademy.com' > All folders. Cuenta cuántas copias hay y a qué hora salió cada una. Dime el resultado: si hay duplicado, no escribas nada al club (disculparse llama más la atención); solo se responde con naturalidad si ellos lo mencionan. | G13: Outlook buscador | H13: 5 | I13: Hecho | J13: Søreide: 1 envío (14/10 8:34). Holbeach: 2 confirmados (13/10 18:50 y 14/10 4:41) y el de ~8:30 no localizado.
A14: 46309 | B14: Miércoles | C14: Libre | D14: Transversal | E14: Opcional: pruebas de envío programado en Apple Mail (máx. 15 min) | F14: Programa un correo a ti mismo a 10 minutos con (1) Mail abierto y el Mac despierto, (2) Mail cerrado, (3) Mac en reposo. Anota cuál sale. Si ninguno funciona con el Mac apagado, no se programa: se envía a mano a las 07:30. | G14: Mail de Apple | H14: 15 | I14: Pendiente
A15: 46309 | B15: Miércoles | C15: Libre | D15: Transversal | E15: Prueba de spam con Microsoft (antes del lote del jueves) | F15: Tres de los cinco clubes del jueves y Hastings usan correo Microsoft 365, que es el filtro más estricto con dominios nuevos. Manda el correo de Whitehaven (texto normal) a una cuenta Outlook o Hotmail (la tuya, de un amigo o una gratuita que crees tú) y mira si cae en Recibidos o en Correo no deseado. Cuéntame el resultado. Si cae en spam, lo marcas 'No es spam' y repetimos mañana. | G15: Chat con Claude | H15: 10 | I15: Pendiente
A16: 46309 | B16: Miércoles | C16: 12:00 | D16: Becas | E16: Daniel (MLS NEXT): enviar el follow-up por Instagram | F16: No contestó a tu mensaje del 21/09. Mi consejo: un único follow-up corto con salida fácil, y si no responde en 7 días, pasarlo a 'Frío'. Texto en 'Respuestas tipo' (Daniel). Mejor entre las 12:00 y las 14:00 de Nueva York (18:00 a 20:00 en España, cuando está libre de clase). Después apunta en el CRM la fecha de envío. | G16: Textos para copiar (Respuestas tipo) | H16: 5 | I16: Hecho | J16: Enviado el 14/10
A17: 46309 | B17: Miércoles | C17: Tarde | D17: Team/Coach | E17: Programar en Apple Mail los envíos del jueves 15/10 | F17: Para cada correo: copia Para, Asunto y Texto de la hoja 'Textos para copiar' (filtra por la fecha 15/10). Revisa en 30 segundos: saludo, nombre del club, firma, sin adjuntos. En Mail: flecha junto a Enviar > Enviar más tarde > fecha y hora indicadas. • IA Akranes | Email 1 | programar para las 05:30 hora Nueva York (09:30 allí) • Maidstone United | Email 1 | programar para las 04:30 hora Nueva York (09:30 allí) • Whitehaven AFC | Email 1 | programar para las 04:30 hora Nueva York (09:30 allí) Regla: una vez programado, NO lo envíes a mano (se duplicaría). Si a las 08:00 no aparece enviado, entonces sí. | G17: Textos para copiar | H17: 30 | I17: Hecho | J17: Programados los 3 (confirmar mañana a las 08:00)
A18: 46310 | B18: Jueves | C18: 04:30 | D18: Team/Coach | E18: ENVIAR email 1 a Maidstone United | F18: Sale a las 04:30 hora Nueva York (09:30 allí) si lo programaste la víspera. No hace falta hacer nada a esta hora. Si es follow-up, se envía respondiendo al correo original (búscalo por destinatario en Outlook o Mail y pulsa Responder). | G18: Textos para copiar | I18: Pendiente
A19: 46310 | B19: Jueves | C19: 04:30 | D19: Team/Coach | E19: ENVIAR email 1 a Whitehaven AFC | F19: Sale a las 04:30 hora Nueva York (09:30 allí) si lo programaste la víspera. No hace falta hacer nada a esta hora. Si es follow-up, se envía respondiendo al correo original (búscalo por destinatario en Outlook o Mail y pulsa Responder). | G19: Textos para copiar | I19: Pendiente
A20: 46310 | B20: Jueves | C20: 05:30 | D20: Team/Coach | E20: ENVIAR email 1 a IA Akranes | F20: Sale a las 05:30 hora Nueva York (09:30 allí) si lo programaste la víspera. No hace falta hacer nada a esta hora. Si es follow-up, se envía respondiendo al correo original (búscalo por destinatario en Outlook o Mail y pulsa Responder). | G20: Textos para copiar | I20: Pendiente
A21: 46310 | B21: Jueves | C21: 8:00 | D21: Todos | E21: Revisión diaria: bandeja, Instagram, WhatsApp | F21: 1) Outlook: mira Recibidos y busca rebotes (correos del sistema que dicen 'Undeliverable' o 'permanent fatal errors'). 2) Instagram y WhatsApp: responde a todo lo que haya entrado, máximo 12 h de espera. 3) Si un club ha contestado: para su cadencia y usa 'Respuestas tipo' en la hoja Textos para copiar. | G21: Textos para copiar (final de la hoja) | H21: 15 | I21: Pendiente
A22: 46310 | B22: Jueves | C22: 8:00 | D22: Team/Coach | E22: Confirmar que salieron los correos de hoy y mirar rebotes | F22: Para cada correo: en Outlook, buscador > escribe el destinatario > 'All folders' (el correo puede estar en 'INBOX.Sent' o 'Sent Messages', no solo en 'Sent'); o en Mail, mira el buzón Enviados. Si aparece: marca Hecho en 'Textos para copiar'. Si NO aparece: envíalo ya a mano. Después mira Recibidos por si hay rebote ('Undeliverable' o 'permanent fatal errors'); si lo hay, anótalo y avísame. | G22: Outlook buscador / Mail Enviados | H22: 10 | I22: Pendiente
A23: 46310 | B23: Jueves | C23: Libre | D23: Becas | E23: Darme tu feedback sobre la ficha de Becas EEUU | F23: Ábrela (02-sales/assets/Always-Up-Becas-EEUU.pdf) y dime qué cambiarías. Antes de cambiar nada te digo si me parece buena idea. | G23: 02-sales/assets | H23: 15 | I23: Pendiente
A24: 46310 | B24: Jueves | C24: Libre | D24: Team/Coach | E24: Pedir al club irlandés testimonio y presentaciones | F24: Es lo que más puede acelerar ventas: un club que ya compró habla mejor de nosotros que cualquier email. Texto en 'Respuestas tipo'. Puedes mandarlo tú o Enrique. | G24: Textos para copiar (Respuestas tipo) | H24: 15 | I24: Pendiente
A25: 46310 | B25: Jueves | C25: Libre | D25: Transversal | E25: Calentar el dominio: 2 o 3 correos reales más a gente de confianza (ya hiciste 3) | F25: Escribe desde alwaysup.es a 2 o 3 personas más (familia, amigos, conocidos con Gmail, Outlook o iCloud) un correo normal con una pregunta, y pídeles que respondan. Si caen en spam, que lo marquen como 'No es spam'. Es la forma más rápida de mejorar la reputación de un dominio nuevo. | H25: 15 | I25: Pendiente
A26: 46310 | B26: Jueves | C26: Libre | D26: Team/Coach | E26: LinkedIn: conectar con Georgia Townsend (Hastings United) | F26: A mano en LinkedIn: perfil de la persona > Conectar > Añadir nota > pegar el texto (máx. 300 caracteres). Si no deja añadir nota, conecta sin nota y manda el texto cuando acepte. Texto: «Hi Georgia, I'm Joel, I run Always Up. We take youth teams to Spain to train with Atlético de Madrid and Real Sociedad. I emailed you this week and thought I'd connect here too. Joel» | G26: Textos para copiar | H26: 5 | I26: Pendiente
A27: 46311 | B27: Viernes | C27: 8:00 | D27: Todos | E27: Revisión diaria: bandeja, Instagram, WhatsApp | F27: 1) Outlook: mira Recibidos y busca rebotes (correos del sistema que dicen 'Undeliverable' o 'permanent fatal errors'). 2) Instagram y WhatsApp: responde a todo lo que haya entrado, máximo 12 h de espera. 3) Si un club ha contestado: para su cadencia y usa 'Respuestas tipo' en la hoja Textos para copiar. | G27: Textos para copiar (final de la hoja) | H27: 15 | I27: Pendiente
A28: 46311 | B28: Viernes | C28: Libre | D28: Todos | E28: Revisión semanal 1: qué ha pasado esta semana | F28: Mira la hoja Hoy y anota respuestas, rebotes y llamadas. Pásame un resumen de tres líneas: yo ajusto el plan. | G28: Hoy | H28: 20 | I28: Pendiente
A29: 46311 | B29: Viernes | C29: Libre | D29: Team/Coach | E29: LinkedIn: conectar con Callum Lawe (Holbeach United) | F29: A mano en LinkedIn: perfil de la persona > Conectar > Añadir nota > pegar el texto (máx. 300 caracteres). Si no deja añadir nota, conecta sin nota y manda el texto cuando acepte. Texto: «Hi Callum, I'm Joel, I run Always Up. We take youth teams to Spain to train with Atlético de Madrid and Real Sociedad. I emailed you this week and thought I'd connect here too. Joel» | G29: Textos para copiar | H29: 5 | I29: Pendiente
A30: 46311 | B30: Viernes | C30: Libre | D30: Team/Coach | E30: LinkedIn: conectar con Marius Engen (Søreide IL) | F30: A mano en LinkedIn: perfil de la persona > Conectar > Añadir nota > pegar el texto (máx. 300 caracteres). Si no deja añadir nota, conecta sin nota y manda el texto cuando acepte. Texto: «Hi Marius, I'm Joel, I run Always Up. We take youth teams to Spain to train with Atlético de Madrid and Real Sociedad. I emailed you this week and thought I'd connect here too. Joel» | G30: Textos para copiar | H30: 5 | I30: Pendiente
A31: 46311 | B31: Viernes | C31: Libre | D31: Todos | E31: Actualizar el CRM con lo que ha pasado esta semana | F31: Estado y fecha de último contacto de cada club o lead. Así la hoja Hoy cuenta bien. | G31: Segmento A, B, C | H31: 15 | I31: Pendiente
A32: 46312 | B32: Sábado | C32: Libre | D32: Instagram | E32: Sesión de redes sociales y marca personal con Claude (30 a 60 min) | F32: Objetivo: 10.000 seguidores antes de fin de 2026. Salir con un plan de contenido de 4 semanas. Hasta tener este plan no se publica nada. Sin fotos de menores identificables. | G32: Chat con Claude | H32: 60 | I32: Pendiente
A33: SEMANA 19/10 a 25/10
A34: 46314 | B34: Lunes | C34: 8:00 | D34: Todos | E34: Revisión diaria: bandeja, Instagram, WhatsApp | F34: 1) Outlook: mira Recibidos y busca rebotes (correos del sistema que dicen 'Undeliverable' o 'permanent fatal errors'). 2) Instagram y WhatsApp: responde a todo lo que haya entrado, máximo 12 h de espera. 3) Si un club ha contestado: para su cadencia y usa 'Respuestas tipo' en la hoja Textos para copiar. | G34: Textos para copiar (final de la hoja) | H34: 15 | I34: Pendiente
A35: 46314 | B35: Lunes | C35: Libre | D35: Team/Coach | E35: Pedirme: «investiga 10 clubes más» para la siguiente tanda | F35: Escríbeme esa frase. Yo verifico decisor y email en la web del club y te dejo los correos listos en esta hoja antes del jueves. | G35: Chat con Claude | H35: 5 | I35: Pendiente
A36: 46314 | B36: Lunes | C36: Libre | D36: Becas | E36: Revisar leads de becas con acción vencida | F36: Pestaña Segmento C - Becas: ordena por 'Próxima acción'. Contesta o actualiza todo lo atrasado. Aplica las 4 preguntas de cualificación. | G36: Segmento C - Becas | H36: 20 | I36: Pendiente
A37: 46314 | B37: Lunes | C37: Libre | D37: Team/Coach | E37: LinkedIn: conectar con Luke Johnston (Whitehaven AFC) | F37: A mano en LinkedIn: perfil de la persona > Conectar > Añadir nota > pegar el texto (máx. 300 caracteres). Si no deja añadir nota, conecta sin nota y manda el texto cuando acepte. Texto: «Hi Luke, I'm Joel, I run Always Up. We take youth teams to Spain to train with Atlético de Madrid and Real Sociedad. I emailed you this week and thought I'd connect here too. Joel» | G37: Textos para copiar | H37: 5 | I37: Pendiente
A38: 46314 | B38: Lunes | C38: Libre | D38: Team/Coach | E38: LinkedIn: 10 minutos de actividad | F38: Acepta conexiones, comenta tres publicaciones de entrenadores o clubes con algo de valor (no publicidad). Eso hace que te vean antes de que llegue el email. | H38: 10 | I38: Pendiente
A39: 46314 | B39: Lunes | C39: Tarde | D39: Team/Coach | E39: Programar en Apple Mail los envíos del martes 20/10 | F39: Para cada correo: copia Para, Asunto y Texto de la hoja 'Textos para copiar' (filtra por la fecha 20/10). Revisa en 30 segundos: saludo, nombre del club, firma, sin adjuntos. En Mail: flecha junto a Enviar > Enviar más tarde > fecha y hora indicadas. • FC Porte d'Aquitaine | Email 1 | programar para las 03:30 hora Nueva York (09:30 allí) • Hastings United | Follow-up 1 | programar para las 04:30 hora Nueva York (09:30 allí) • Home Farm FC | Follow-up 1 | programar para las 04:30 hora Nueva York (09:30 allí) • Virtu Academy | Email 1 | programar para las 04:30 hora Nueva York (09:30 allí) Regla: una vez programado, NO lo envíes a mano (se duplicaría). Si a las 08:00 no aparece enviado, entonces sí. | G39: Textos para copiar | H39: 35 | I39: Pendiente
A40: 46315 | B40: Martes | C40: 03:30 | D40: Team/Coach | E40: ENVIAR email 1 a FC Porte d'Aquitaine | F40: Sale a las 03:30 hora Nueva York (09:30 allí) si lo programaste la víspera. No hace falta hacer nada a esta hora. Si es follow-up, se envía respondiendo al correo original (búscalo por destinatario en Outlook o Mail y pulsa Responder). | G40: Textos para copiar | I40: Pendiente
A41: 46315 | B41: Martes | C41: 04:30 | D41: Team/Coach | E41: ENVIAR follow-up 1 a Hastings United | F41: Sale a las 04:30 hora Nueva York (09:30 allí) si lo programaste la víspera. No hace falta hacer nada a esta hora. Si es follow-up, se envía respondiendo al correo original (búscalo por destinatario en Outlook o Mail y pulsa Responder). | G41: Textos para copiar | I41: Pendiente
...

Sheet Hoy
A1: Plan de ventas — panel diario Always Up
A2: Actualizar cada día de trabajo. Fecha de última actualización: | E2: =TODAY()
A4: 🔴 URGENTE — mirar esto primero
A5: Qué | B5: Cuántos ahora (se calcula solo)
A6: Follow-ups de clubes atrasados (enviado hace más de 10 días, sin respuesta) | B6: =COUNTIFS('Segmento A - Clubes'!I2:I300,"Enviado",'Segmento A - Clubes'!M2:M300,"<>",'Segmento A - Clubes'!M2:M300,"<"&(TODAY()-10))+COUNTIFS('Segmento B - America'!H2:H300,"Enviado",'Segmento B - America'!L2:L300,"<>",'Segmento B - America'!L2:L300,"<"&(TODAY()-10))
A7: Leads de becas con llamada agendada (confirmar/preparar) | B7: =COUNTIF('Segmento C - Becas'!E2:E300,"Llamada agendada")
A8: Leads de becas cualificados sin próxima acción clara desde hace tiempo (revisar a mano) | B8: =COUNTIF('Segmento C - Becas'!E2:E300,"Cualificado")
A10: 🟠 OUTBOUND — lo que generas tú hoy
A11: Métrica | B11: Meta semanal | C11: Hecho hoy (rellenar tú)
A12: Nuevos clubes/academias investigados con decisor y email verificados | B12: 10
A13: Emails de outreach nuevos enviados | B13: 5 a 8
A14: Conexiones de LinkedIn con nota personalizada | B14: 5
A17: 🟢 INBOUND — lo que te llega a ti
A18: Qué | B18: Cuántos ahora (se calcula solo)
A19: Leads de becas nuevos sin cualificar todavía | B19: =COUNTIF('Segmento C - Becas'!E2:E300,"Nuevo")
A21: 📊 PIPELINE — resumen por segmento (detalle completo en pestaña Dashboard)
A22: Segmento | B22: Total en lista | C22: Listo para enviar | D22: Enviado | E22: Respondido | F22: Llamada agendada | G22: Cerrado
A23: Segmento A — Clubes juveniles | B23: =COUNTA('Segmento A - Clubes'!A2:A300) | C23: =COUNTIF('Segmento A - Clubes'!I2:I300,"Listo para enviar") | D23: =COUNTIF('Segmento A - Clubes'!I2:I300,"Enviado") | E23: =COUNTIF('Segmento A - Clubes'!I2:I300,"Respondido") | F23: =COUNTIF('Segmento A - Clubes'!I2:I300,"Llamada agendada") | G23: =COUNTIF('Segmento A - Clubes'!I2:I300,"Cerrado")
A24: Segmento B — Univ./clubes América | B24: =COUNTA('Segmento B - America'!A2:A300) | C24: =COUNTIF('Segmento B - America'!H2:H300,"Listo para enviar") | D24: =COUNTIF('Segmento B - America'!H2:H300,"Enviado") | E24: =COUNTIF('Segmento B - America'!H2:H300,"Respondido") | F24: =COUNTIF('Segmento B - America'!H2:H300,"Llamada agendada") | G24: =COUNTIF('Segmento B - America'!H2:H300,"Cerrado")
A26: Segmento C — Becas
A27: Etapa | B27: Total
A28: Nuevo | B28: =COUNTIF('Segmento C - Becas'!E2:E300,"Nuevo")
A29: Cualificado | B29: =COUNTIF('Segmento C - Becas'!E2:E300,"Cualificado")
A30: Llamada agendada | B30: =COUNTIF('Segmento C - Becas'!E2:E300,"Llamada agendada")
A31: Llamada realizada | B31: =COUNTIF('Segmento C - Becas'!E2:E300,"Llamada realizada")
A32: Cerrado | B32: =COUNTIF('Segmento C - Becas'!E2:E300,"Cerrado")
A33: Perdido | B33: =COUNTIF('Segmento C - Becas'!E2:E300,"Perdido")

Sheet Textos para copiar
A1: Textos para copiar y pegar
A2: Una fila por envío, ordenada por fecha. Filtra la columna Fecha para ver solo el día que toca. Copia Para, Asunto y Texto sin cambiar nada: la firma ya va incluida. Hora = a qué hora de Nueva York programar el envío (son las 09:30 en el país del club). Los textos están revisados por Claude: sin guiones largos, sin placeholders, saludo a una sola persona.
A4: Fecha | B4: Día | C4: Programar para (NY) | D4: Club | E4: Tipo | F4: Para | G4: Asunto | H4: Texto para pegar | I4: Cómo enviarlo | J4: Hecho (fecha real) | K4: Qué hacer si...
A5: 46309 | B5: Miércoles | C5: 04:30 (09:30 allí) | D5: Holbeach United | E5: Email 1 | F5: callum@holbeachunitedacademy.com | G5: A week in Spain for Holbeach's academy squads | H5: Hi Callum, I'm Joel, I run Always Up. We take youth teams to Spain for a week of training at Atlético de Madrid and Real Sociedad facilities, with matches against local academy sides, a stadium tour, and accommodation and meals all sorted. I saw Holbeach was down for the Costa Daurada Cup this year, and your Football & Education Academy made me think a week like this could suit your older squads. One of our partner clubs in Ireland won their first ever league title after a few years of coming out with us, and their coaches said the trip helped. Would you be up for a quick call next week? If you'd rather see the details first, I'm happy to send a short overview. Best, Joel Martinez Founder, Always Up joel.martinez@alwaysup.es | +1 (814) 329 1929 | alwaysup.es | I5: En Mail: correo nuevo desde joel.martinez@alwaysup.es. Pega Para, Asunto y Texto tal cual (la firma ya va dentro). Sin adjuntos. Flecha junto a Enviar > Enviar más tarde > fecha y la hora de la columna C. Una vez programado, no lo envíes a mano. | K5: Rebota: avísame y busco otra dirección. Contesta: para la cadencia y mira 'Respuestas tipo' abajo.
A6: 46309 | B6: Miércoles | C6: 03:30 (09:30 allí) | D6: Søreide IL | E6: Email 1 | F6: fotball@soreideil.no | G6: A week in Spain for Søreide's youth teams | H6: Hi Marius and Gunn, I'm Joel, I run Always Up. My first email bounced from your youth committee address, so I'm writing to you directly. We take youth teams to Spain for a week of training at Atlético de Madrid and Real Sociedad facilities, with matches against local academy sides and accommodation and meals all sorted. I saw Søreide was down for the Costa Daurada Cup this summer, so Spain may already be on your radar. One of our partner clubs in Ireland won their first ever league title after a few years with us. Would you be up for a quick call next week? Or I can send a short overview first if that's easier. Best, Joel Martinez Founder, Always Up joel.martinez@alwaysup.es | +1 (814) 329 1929 | alwaysup.es | I6: En Mail: correo nuevo desde joel.martinez@alwaysup.es. Pega Para, Asunto y Texto tal cual (la firma ya va dentro). Sin adjuntos. Flecha junto a Enviar > Enviar más tarde > fecha y la hora de la columna C. Una vez programado, no lo envíes a mano. | K6: Rebota: avísame y busco otra dirección. Contesta: para la cadencia y mira 'Respuestas tipo' abajo.
A7: 46310 | B7: Jueves | C7: Libre | D7: Hastings United (Girls Academy) | E7: LinkedIn conectar | F7: Georgia Townsend | G7: (nota de conexión) | H7: Hi Georgia, I'm Joel, I run Always Up. We take youth teams to Spain to train with Atlético de Madrid and Real Sociedad. I emailed you this week and thought I'd connect here too. Joel | I7: A mano en LinkedIn: perfil de la persona > Conectar > Añadir nota > pegar el texto (máx. 300 caracteres). Si no deja añadir nota, conecta sin nota y manda el texto cuando acepte. | K7: Si acepta, no mandes más mensajes hasta que conteste al email.
A8: 46310 | B8: Jueves | C8: 05:30 (09:30 allí) | D8: IA Akranes | E8: Email 1 | F8: kfia@ia.is | G8: A question about youth trips to Spain | H8: Hi ÍA team, I'm Joel, I run Always Up. We take youth teams to Spain for a week of training at Atlético de Madrid and Real Sociedad facilities, with matches against local academy sides, a stadium tour, and accommodation and meals all sorted. I saw ÍA Akranes was down for the Costa Daurada Cup this year. Could you point me to the person who looks after trips abroad for your youth teams? One of our partner clubs in Ireland won their first ever league title after a few years with us, so I'd be glad to share how it went for them. Thanks a lot, Joel Martinez Founder, Always Up joel.martinez@alwaysup.es | +1 (814) 329 1929 | alwaysup.es | I8: En Mail: correo nuevo desde joel.martinez@alwaysup.es. Pega Para, Asunto y Texto tal cual (la firma ya va dentro). Sin adjuntos. Flecha junto a Enviar > Enviar más tarde > fecha y la hora de la columna C. Una vez programado, no lo envíes a mano. | K8: Rebota: avísame y busco otra dirección. Contesta: para la cadencia y mira 'Respuestas tipo' abajo.
A9: 46310 | B9: Jueves | C9: 04:30 (09:30 allí) | D9: Maidstone United (Girls Development Centre) | E9: Email 1 | F9: info@maidstoneunited.co.uk | G9: A question about the Girls Development Centre | H9: Hi team, I'm Joel, I run Always Up. We take youth teams to Spain for a week of training at Atlético de Madrid and Real Sociedad facilities, with matches against local academy sides, a stadium tour, and accommodation and meals all sorted. I saw Maidstone United was down for the Costa Daurada Cup this summer and thought your Girls Development Centre could be a great fit. Could you point me to the right person to talk to about trips for the girls teams? One of our partner clubs in Ireland won their first ever league title after a few years with us, so I'd be glad to share how it went for them. Thanks a lot, Joel Martinez Founder, Always Up joel.martinez@alwaysup.es | +1 (814) 329 1929 | alwaysup.es | I9: En Mail: correo nuevo desde joel.martinez@alwaysup.es. Pega Para, Asunto y Texto tal cual (la firma ya va dentro). Sin adjuntos. Flecha junto a Enviar > Enviar más tarde > fecha y la hora de la columna C. Una vez programado, no lo envíes a mano. | K9: Rebota: avísame y busco otra dirección. Contesta: para la cadencia y mira 'Respuestas tipo' abajo.
A10: 46310 | B10: Jueves | C10: 04:30 (09:30 allí) | D10: Whitehaven AFC (Juniors Girls U13-U15) | E10: Email 1 | F10: Luke.johnston@whitehavenafc.com | G10: A week in Spain for Whitehaven's girls teams | H10: Hi Luke, I'm Joel, I run Always Up. We take youth teams to Spain for a week of training at Atlético de Madrid and Real Sociedad facilities, with matches against local academy sides, a stadium tour, and accommodation and meals all sorted. I saw Whitehaven was down for the Costa Daurada Cup this summer, and that the club has girls teams from under 9 up to under 16, so I thought this could be a good fit. Would you be up for a quick call next week, or would you like a short overview first? And if you're not the right person, could you point me to whoever organises trips for the girls section? Best, Joel Martinez Founder, Always Up joel.martinez@alwaysup.es | +1 (814) 329 1929 | alwaysup.es | I10: En Mail: correo nuevo desde joel.martinez@alwaysup.es. Pega Para, Asunto y Texto tal cual (la firma ya va dentro). Sin adjuntos. Flecha junto a Enviar > Enviar más tarde > fecha y la hora de la columna C. Una vez programado, no lo envíes a mano. | K10: Rebota: avísame y busco otra dirección. Contesta: para la cadencia y mira 'Respuestas tipo' abajo.
A11: 46311 | B11: Viernes | C11: Libre | D11: Holbeach United | E11: LinkedIn conectar | F11: Callum Lawe | G11: (nota de conexión) | H11: Hi Callum, I'm Joel, I run Always Up. We take youth teams to Spain to train with Atlético de Madrid and Real Sociedad. I emailed you this week and thought I'd connect here too. Joel | I11: A mano en LinkedIn: perfil de la persona > Conectar > Añadir nota > pegar el texto (máx. 300 caracteres). Si no deja añadir nota, conecta sin nota y manda el texto cuando acepte. | K11: Si acepta, no mandes más mensajes hasta que conteste al email.
A12: 46311 | B12: Viernes | C12: Libre | D12: Søreide IL | E12: LinkedIn conectar | F12: Marius Engen | G12: (nota de conexión) | H12: Hi Marius, I'm Joel, I run Always Up. We take youth teams to Spain to train with Atlético de Madrid and Real Sociedad. I emailed you this week and thought I'd connect here too. Joel | I12: A mano en LinkedIn: perfil de la persona > Conectar > Añadir nota > pegar el texto (máx. 300 caracteres). Si no deja añadir nota, conecta sin nota y manda el texto cuando acepte. | K12: Si acepta, no mandes más mensajes hasta que conteste al email.
A13: 46314 | B13: Lunes | C13: Libre | D13: Whitehaven AFC (Juniors Girls U13-U15) | E13: LinkedIn conectar | F13: Luke Johnston | G13: (nota de conexión) | H13: Hi Luke, I'm Joel, I run Always Up. We take youth teams to Spain to train with Atlético de Madrid and Real Sociedad. I emailed you this week and thought I'd connect here too. Joel | I13: A mano en LinkedIn: perfil de la persona > Conectar > Añadir nota > pegar el texto (máx. 300 caracteres). Si no deja añadir nota, conecta sin nota y manda el texto cuando acepte. | K13: Si acepta, no mandes más mensajes hasta que conteste al email.
A14: 46315 | B14: Martes | C14: 03:30 (09:30 allí) | D14: FC Porte d'Aquitaine | E14: Email 1 | F14: math.bachowski.mb@gmail.com | G14: Une semaine en Espagne pour les jeunes du FC Porte d'Aquitaine | H14: Bonjour Mathieu, Je m'appelle Joel et je dirige Always Up. Nous emmenons des équipes de jeunes en Espagne pour une semaine d'entraînement dans les installations de l'Atlético de Madrid et de la Real Sociedad, avec des matchs contre des équipes de centres de formation locaux, la visite d'un stade, l'hébergement et les repas. J'ai vu que le FC Porte d'Aquitaine était inscrit à la Costa Daurada Cup cet été, et je me suis dit que cela pourrait intéresser vos U15 ou U17. Un de nos clubs partenaires en Irlande a remporté son premier titre de champion après quelques années avec nous. Auriez-vous quelques minutes pour un appel la semaine prochaine ? Sinon, je peux d'abord vous envoyer une courte présentation. Cordialement, Joel Martinez Founder, Always Up joel.martinez@alwaysup.es | +1 (814) 329 1929 | alwaysup.es | I14: En Mail: correo nuevo desde joel.martinez@alwaysup.es. Pega Para, Asunto y Texto tal cual (la firma ya va dentro). Sin adjuntos. Flecha junto a Enviar > Enviar más tarde > fecha y la hora de la columna C. Una vez programado, no lo envíes a mano. | K14: Rebota: avísame y busco otra dirección. Contesta: para la cadencia y mira 'Respuestas tipo' abajo.
A15: 46315 | B15: Martes | C15: 04:30 (09:30 allí) | D15: Hastings United (Girls Academy) | E15: Follow-up 1 | F15: georgia.townsend@hastingsunited.com | G15: Re: Bringing Hastings United's Girls Academy to train with LaLiga clubs in Spain | H15: Hi Georgia, Just following up on my email from last week in case it got buried. To give you an idea, a typical week is five days in Madrid. Training sessions, matches against local academy teams, a tour of the Metropolitano and the stadium museum, and accommodation and meals all sorted by us. If you're thinking about Easter or summer 2027, now is a good time to look at dates. Happy to jump on a quick call, or send the details by email if that's easier. Best, Joel Martinez Founder, Always Up joel.martinez@alwaysup.es | +1 (814) 329 1929 | alwaysup.es | I15: Busca el correo original por destinatario (Outlook buscador > All folders, o Mail > Enviados) y pulsa Responder para que quede en el mismo hilo. Pega el texto. Sin adjuntos. Envíalo más tarde a la hora de la columna C. Antes, mira en el CRM que no haya contestado por otro canal. | K15: Si ya contestó por otro canal, no lo envíes.
A16: 46315 | B16: Martes | C16: 04:30 (09:30 allí) | D16: Home Farm FC (chicas U13-U15) | E16: Follow-up 1 | F16: homefarmfc@gmail.com | G16: Re: Bringing Home Farm FC to train with Atlético de Madrid & Real Sociedad in Spain | H16: Hi all, Just following up on my email from last week in case it got buried. To give you an idea, a typical week is five days in Madrid. Training sessions, matches against local academy teams, a tour of the Metropolitano and the stadium museum, and accommodation and meals all sorted by us. If you're thinking about Easter or summer 2027, now is a good time to look at dates. Happy to jump on a quick call, or send the details by email if that's easier. Best, Joel Martinez Founder, Always Up joel.martinez@alwaysup.es | +1 (814) 329 1929 | alwaysup.es | I16: Busca el correo original por destinatario (Outlook buscador > All folders, o Mail > Enviados) y pulsa Responder para que quede en el mismo hilo. Pega el texto. Sin adjuntos. Envíalo más tarde a la hora de la columna C. Antes, mira en el CRM que no haya contestado por otro canal. | K16: Si ya contestó por otro canal, no lo envíes.
... A51: 46336 | B51: Martes | C51: 04:30 (09:30 allí) | D51: Virtu Academy | E51: Cierre | F51: info@virtuacademy.co.uk | G51: Re: A question about trips to Spain for Virtu | H51: Hi team, I haven't heard back, so I'll assume the timing isn't right and I won't keep emailing. If anything changes, or you'd like the details for later, just reply here. Wishing Virtu Academy a great season. Best, Joel Martinez Founder, Always Up joel.martinez@alwaysup.es | +1 (814) 329 1929 | alwaysup.es | I51: Busca el correo original por destinatario (Outlook buscador > All folders, o Mail > Enviados) y pulsa Responder para que quede en el mismo hilo. Pega el texto. Sin adjuntos. Envíalo más tarde a la hora de la columna C. Antes, mira en el CRM que no haya contestado por otro canal. | K51: Tras este correo, pasa el club a 'Retomar en enero 2027' en el CRM.
A54: RESPUESTAS TIPO Y OTROS TEXTOS (para cuando contestan o para casos concretos)
D55: Responde: quiere hablar | H55: Great, thanks for getting back to me. Would {A} or {B} work for a call? Those are your local times. If neither suits, tell me what does and I'll adapt. I'll send an invite as soon as we pick one. Best, Joel Martinez Founder, Always Up joel.martinez@alwaysup.es | +1 (814) 329 1929 | alwaysup.es | I55: Menos de 4 horas. Sustituye {A} y {B} por dos horarios de la tabla de LEEME convertidos a su hora. Si prefiere elegir él: ofrece el enlace de Calendly.
D56: Responde: pide información | H56: Of course. I've attached our company overview and the programme sheet for Team Experience. If it's easier to talk it through, I'm happy to jump on a quick call as well, just tell me what time suits you. Best, Joel Martinez Founder, Always Up joel.martinez@alwaysup.es | +1 (814) 329 1929 | alwaysup.es | I56: Adjunta Always-Up-Company-Deck.pdf y Always-Up-Team-Experience.pdf (02-sales/assets). Menos de 4 horas.
D57: Responde: pregunta el precio | H57: It depends on the dates and the size of the group. As a reference, the five day programme starts at around $1,500 per player. A 15 minute call would let me give you an exact figure for your squad. Best, Joel Martinez Founder, Always Up joel.martinez@alwaysup.es | +1 (814) 329 1929 | alwaysup.es | I57: Decisión tuya: dar la referencia (recomendado) o dejar el precio para la llamada.
D58: Responde: ahora no | H58: No problem at all, and thanks for letting me know. Would it be okay if I check back in January, when most clubs start planning Easter and summer 2027? Best, Joel Martinez Founder, Always Up joel.martinez@alwaysup.es | +1 (814) 329 1929 | alwaysup.es | I58: Apunta en el CRM: Retomar enero 2027, con fecha.
D59: Responde: no soy la persona | H59: Thanks, that's really helpful. Could you share their name and email? I'll mention that you pointed me their way. Best, Joel Martinez Founder, Always Up joel.martinez@alwaysup.es | +1 (814) 329 1929 | alwaysup.es | I59: Luego escribe al nombre que te den (usa un email 1 con su nombre) y menciona a quien te derivó.
D60: Daniel (MLS NEXT): follow-up por Instagram | H60: Hola Daniel, ¿qué tal? Hace unas semanas hablamos de tu duda entre 1º y 2º de Bachillerato y de cómo encajaría con el proceso universitario en EEUU. Te escribo solo para saber si sigues con ganas de explorarlo. Si es así, mándame tu posición y, si tienes, un vídeo o enlace de algún partido de la MLS NEXT, y te cuento con calma qué opciones reales habría en tu caso. Cuanto antes lo veamos, más margen hay para decidir bien lo del curso. Y si ahora no es el momento, no pasa nada, dímelo y lo dejamos aquí. | I60: Instagram. Un solo follow-up. Si no contesta en 7 días, pasa a Frío en el CRM. No pidas más datos en este mensaje.
D61: Pedir testimonio y presentaciones al club irlandés | H61: Hi [nombre], hope you and the squad are doing well. I have a small favour to ask. We're building up Always Up and your league title story means a lot to us. Would you be happy to share two or three lines about what the experience did for the players, or even a short video message? And if you know any other clubs who would enjoy a trip like yours, an introduction from you would help us enormously. Thank you so much. Joel | I61: Mándalo tú o Enrique, por WhatsApp. El nombre del contacto lo pones tú. Si dice que sí, pídele una foto del trofeo con los jugadores (con permiso del club).

Sheet Plan por servicio
A1: Plan de captación por servicio
A2: Un único plan para conseguir clientes en todos los servicios, con prioridades. Con 10 a 20 horas semanales no se pueden empujar siete líneas a la vez: se trabajan a fondo las dos primeras, se cuida el resto con contactos cálidos y se documenta lo demás. Detalle completo en 02-sales/plan-captacion-todos-los-servicios.md.
A4: Servicio | B4: Prioridad | C4: Quién compra | D4: Dónde lo encontramos (por orden de rendimiento) | E4: Qué decimos en el primer mensaje | F4: Qué se hace cada semana | G4: Objetivo a 30 días | H4: Material | I4: Límites y riesgos
A5: Team Experience | B5: 1 (principal) | C5: Club o comité de equipos de 12 a 18 años, preferiblemente de los que ya viajan | D5: 1) Email con nombre y apellido (Claude investiga). 2) Referidos del club irlandés. 3) LinkedIn al decisor. 4) DM de Instagram o Facebook del club. 5) Listas de participantes de torneos en España. | E5: Una semana de entrenamiento en las instalaciones de Atlético y Real Sociedad. Pregunta de dos opciones: llamada corta o resumen. | F5: Tanda nueva de 5 a 8 clubes. Follow-ups según calendario. 5 conexiones de LinkedIn. Una petición de referidos. | G5: 25 clubes contactados con nombre, 3 a 5 respuestas, 2 llamadas. | H5: Ficha Team Experience y deck de empresa (solo tras respuesta). | I5: Ciclo largo: el cierre probable es de noviembre a enero. Mucha lista de torneos no sirve: clubes ya inactivos o sin contacto.
A6: Coach Experience | B6: 1 (junto a Team) | C6: Director técnico o entrenadores de los mismos clubes | D6: Se vende en la misma conversación que Team Experience. Después: asociaciones de entrenadores y cursos. | E6: En la llamada: «¿os interesaría también que vuestros entrenadores se formen con la metodología del club?» | F6: Mencionarlo en el 100 % de las llamadas. Una publicación en LinkedIn sobre formación de entrenadores. | G6: Que salga en todas las propuestas como opción. | H6: Ficha Coach Experience. | I6: No hace falta outreach propio todavía. No lo dispersemos.
A7: Becas EEUU (Study & Play USA) | B7: 1 (el que cierra antes) | C7: Familias de jugadores de 14 a 22 años, y sus entrenadores | D7: 1) DMs entrantes de Instagram y WhatsApp. 2) Contenido de Instagram. 3) Entrenadores y academias que recomiendan a sus jugadores. 4) Referidos de familias que ya hablaron con nosotros. | E7: Las 4 preguntas de cualificación (nivel, vídeo, notas, presupuesto del año en EEUU). Nunca prometer beca ni nombrar al partner. | F7: Responder todo en menos de 12 h. Seguimiento a cada lead según etapa. 2 o 3 contenidos. Desde la semana 3: 5 mensajes a entrenadores prescriptores. | G7: 10 leads cualificados, 3 llamadas, 1 cierre (Omar, Daniel o el del béisbol son los más avanzados). | H7: Ficha Becas EEUU + vídeo del jugador. | I7: Depende del nivel real del jugador. No descontar como primera respuesta: primero diagnosticar la objeción.
A8: Campus Internacional (ATM y Real Sociedad fuera de España) | B8: 2 (pocas operaciones, alto valor) | C8: Academias o clubes extranjeros que quieren entrenadores del Atlético o la Real en su ciudad | D8: Contactos cálidos primero: Bélgica, SADE Puerto Rico, Leonardo Uren (Brasil). Sin outreach frío hasta decidir la estructura. | E8: Solo con contactos cálidos, tras decidir estructura A o B con Enrique (23/10). | F8: Retomar los 3 contactos cálidos. Decidir estructura y política de pago. | G8: Decisión tomada y 3 conversaciones activas. | H8: Diapositiva del deck. Ficha pendiente. | I8: Riesgo de caja (cobro 50/50) y de plazas sin llenar. No vender sin decidir quién asume el riesgo.
A9: International Program (Real Sociedad) | B9: 2 | C9: Familias de jugadores de 12 a 18 años y academias extranjeras | D9: Instagram, referidos y los contactos de Puerto Rico y Brasil. No hay outreach frío. | E9: Se ofrece cuando el perfil del lead encaja (edad y nivel), nunca como premio de consolación. | F9: Recoger interés entrante. Preguntar a RS por plazas y plazos 2027. | G9: Respuesta de RS y ficha preparada. | H9: Diapositiva del deck. Ficha pendiente. | I9: Sin fechas de plazas no hay urgencia real. No inventarla.
A10: GEE (colegios privados en EEUU) | B10: 3 | C10: Familias de jugadores de 14 a 17 años que buscan high school privado en EEUU | D10: Dentro de la cualificación de Becas, como opción cuando encaja. Es un partner externo. | E10: Se menciona en la conversación de becas, no es un primer mensaje. | F10: Nada propio. Ficha aparte. | G10: Ficha GEE creada. | H10: Ficha pendiente. | I10: Dependemos del partner. Comprador distinto al de becas universitarias: ficha separada.
A11: Oportunidades profesionales (Alemania y España) y Player Development | B11: 4 (sin estructurar) | C11: Jugadores 16 a 22 años con nivel profesional posible | D11: No hay outreach. Se recoge interés que llegue por Instagram. | E11: Ninguno todavía. | F11: Apuntar interés en 'Oportunidades y notas'. | G11: Ninguno. | H11: Ninguno. | I11: Exposición legal con agentes FIFA y menores: usar siempre agente licenciado y abogado. No empezar hasta tener estructura.
A12: Transversal: marca y canales | B12: Constante | C12: Todos | D12: Instagram (10.000 seguidores a fin de 2026), LinkedIn (perfil terminado y deck público subido), web alwaysup.es, Calendly (pendiente de tu horario). | E12: Siempre la misma promesa: experiencias reales con clubes profesionales. | F12: 3 stories o posts por semana. 10 minutos de LinkedIn en días alternos. | G12: Sesión de redes el 17/10 y plan de 4 semanas. | H12: Perfiles y deck. | I12: Sin fotos de menores identificables.

Sheet Verificación
A1: Verificación de contactos (control de calidad)
A2: Qué he comprobado de cada dirección y con qué fiabilidad. Importante: ningún método permite saber al 100 % que un buzón existe hasta enviar. Por eso, tras cada envío miras los rebotes a los pocos minutos (tarea diaria del calendario). «Dominio recibe correo» significa que el dominio tiene servidor de correo activo.
A4: Club | B4: Email | C4: Fuente | D4: Dominio recibe correo | E4: Estado | F4: Fiabilidad | G4: Plan B si falla
A5: Home Farm FC | B5: homefarmfc@gmail.com | C5: Email del club en dbsportstours; enviado 13/10 | D5: Sí | E5: Entregado (sin rebote a las 21:30 de España) | F5: Alta | G5: Facebook del club
A6: Hastings United | B6: georgia.townsend@hastingsunited.com | C6: Directorio de la academia; enviado 13/10 | D6: Sí | E6: Entregado (sin rebote) | F6: Alta | G6: Instagram del club
A7: Søreide IL | B7: fotball@soreideil.no | C7: soreideil.no/fotball/kontaktinformasjon (publicado por el club) | D7: Sí | E7: Pendiente de enviar | F7: Alta | G7: Facebook del club
A8: Holbeach United | B8: callum@holbeachunitedacademy.com | C8: holbeachunitedcsa.org.uk/contact (Callum Lawe, vicepresidente de la Academia) | D8: Sí | E8: Pendiente de enviar | F8: Alta | G8: info@holbeachunitedcsa.org.uk
A9: Whitehaven AFC | B9: Luke.johnston@whitehavenafc.com | C9: Aparece como email de contacto del club en dos búsquedas. La web no lo muestra en texto (lo comprobé abriendo la página). | D9: Sí | E9: Pendiente de enviar | F9: Media | G9: Facebook de Whitehaven AFC o teléfono +44 1946 692211
A10: Maidstone United | B10: info@maidstoneunited.co.uk | C10: Contacto general del club (búsqueda) | D10: Sí | E10: Pendiente de enviar | F10: Media | G10: Teléfono 078 3585 4704 (Girls Development Centre) o redes
A11: IA Akranes | B11: kfia@ia.is | C11: Contacto del club (kfia.is y búsqueda) | D11: Sí | E11: Pendiente de enviar | F11: Media-alta | G11: Facebook del club
A12: Virtu Academy | B12: info@virtuacademy.co.uk | C12: virtuacademy.co.uk (búsqueda) | D12: Sí | E12: Pendiente de enviar | F12: Media | G12: Instagram del club
A13: FC Porte d'Aquitaine | B13: math.bachowski.mb@gmail.com | C13: Responsable técnico de jóvenes según directorio (búsqueda). Gmail personal. | D13: Sí | E13: Pendiente de enviar | F13: Media | G13: Email oficial del club en la FFF: 560792@lfna.fr
A15: Descartados tras investigar (13/10): Morecambe Hawks United (equipo local pequeño, no encaja), Team ALTI (sin datos fiables), Lower Ormond (existe en la lista de Semana Santa pero no encuentro contacto).
A16: Excelsior Rotterdam: club profesional con academia (Joep Breimer, jefe de desarrollo de la cantera). Perfil distinto, prioridad baja.

Sheet Segmento A - Clubes
A1: Segmento A — Clubes juveniles internacionales
A2: Perfil Greystones/Homefarm: decide un entrenador o comité de club, ciclo de venta corto.
A3: Prioridad principal (ver plan-ventas-maestro.md sección 3). Estado: usar exactamente estos valores para que las fórmulas de la pestaña Hoy funcionen — Pendiente investigar / Listo para enviar / Enviado / Respondido / Llamada agendada / Llamada realizada / Cerrado / Perdido / En negociación / Solo info.
A5: Club/Academia | B5: País | C5: Categoría/Edad | D5: Motivo de interés (contrastado) | E5: Fuente | F5: Contacto (nombre) | G5: Email | H5: Teléfono | I5: Estado | J5: Próxima acción | K5: Asunto email | L5: Cuerpo email | M5: Fecha envío | N5: Fecha último contacto | O5: Notas | P5: Qué adjuntar (por etapa)
A6: Home Farm FC (chicas U13-U15) | B6: Irlanda | C6: U13-U15 chicas | D6: Mismo perfil exacto que Greystones (irlandés, viaja a España) | E6: dbsportstours.com | F6: Karl Higgins (U13) / Mark Kelly (U14) / Aaron Doherty (U15) | G6: homefarmfc@gmail.com | H6: Karl 087-3838347 / Mark 085-1116953 / Aaron 087-6242781 | I6: Enviado | J6: Follow-up 1 el 20/10/2026 en el mismo hilo (enviar a las 07:30 hora Nueva York). Textos en la hoja 'Textos para copiar'. | K6: Bringing Home Farm FC to train with Atlético de Madrid & Real Sociedad in Spain | L6: Hi Karl / Mark / Aaron, I'm Joel, I run Always Up — we bring international youth clubs to Spain to train directly at the facilities of Atletico de Madrid, Real Sociedad and Sporting de Gijon. I came across Home Farm FC's girls programme and thought this could be a great fit — same profile as one of our longtime Irish partner clubs. After 3 years training with us, that club won their first league title in the club's history, and their coaches credited part of it to the experience: 'No doubt our Atletico de Madrid Experience helped us win our league title... it gives players the belief they are special.' And with Spain now World Cup Champions, there's never been a better time for international teams to train and compete on Spanish soil. Would you have 15 minutes this week to hear more? Best, Joel | M6: 46308 | N6: 46308 | O6: Email ya preparado y revisado 2026-08-29 — solo falta que Joel lo envíe | Enviado 13/10/2026 a las 15:23 (hora de Nueva York) desde joel.martinez@alwaysup.es, solo texto, sin firma ni adjuntos | P6: 1er email: NADA adjunto, solo texto (firma de texto plano). Si responde con interés: ficha Always-Up-Team-Experience.pdf. Antes de la llamada: deck de empresa (pendiente de crear), solo si hace falta. Tras la llamada: propuesta escrita.
A7: Søreide IL | B7: Noruega | C7: Sin confirmar | D7: Participante confirmado Costa Daurada Cup 2026 | E7: costadauradacup.com | F7: Marius Engen (sportslig leder) / Gunn Eklund Breisnes (leder) | G7: fotball@soreideil.no | I7: Listo para enviar | J7: Enviar el 14/10/2026 a las 07:30 hora Nueva York. Textos en la hoja 'Textos para copiar'. | K7: A week in Spain for Søreide's youth teams | L7: Hi Marius and Gunn, I'm Joel, I run Always Up. My first email bounced from your youth committee address, so I'm writing to you directly. We take youth teams to Spain for a week of training at Atlético de Madrid and Real Sociedad facilities, with matches against local academy sides and accommodation and meals all sorted. I saw Søreide was down for the Costa Daurada Cup this summer, so Spain may already be on your radar. One of our partner clubs in Ireland won their first ever league title after a few years with us. Would you be up for a quick call next week? Or I can send a short overview first if that's easier. Best, Joel Martinez Founder, Always Up joel.martinez@alwaysup.es | +1 (814) 329 1929 | alwaysup.es | M7: 46308 | N7: 46308 | O7: 13/10/2026: el email 1 REBOTÓ (ungdomsutvalget@soreideil.no reenvía a una cuenta inexistente en bergensskolen.com). Contactos reales en soreideil.no/fotball/kontaktinformasjon. Reenvío el 14/10 a fotball@soreideil.no. | P7: 1er email: NADA adjunto, solo texto (firma de texto plano). Si responde con interés: ficha Always-Up-Team-Experience.pdf. Antes de la llamada: deck de empresa (pendiente de crear), solo si hace falta. Tras la llamada: propuesta escrita.
A8: Maidstone United (Girls Development Centre) | B8: Reino Unido | C8: Sin confirmar | D8: Participante confirmado Costa Daurada Cup 2026 | E8: costadauradacup.com | F8: Sin nombre confirmado | G8: info@maidstoneunited.co.uk | H8: 078 3585 4704 | I8: Listo para enviar | J8: Enviar el 15/10/2026 a las 07:30 hora Nueva York. Textos en la hoja 'Textos para copiar'. | K8: A question about the Girls Development Centre | L8: Hi team, I'm Joel, I run Always Up. We take youth teams to Spain for a week of training at Atlético de Madrid and Real Sociedad facilities, with matches against local academy sides, a stadium tour, and accommodation and meals all sorted. I saw Maidstone United was down for the Costa Daurada Cup this summer and thought your Girls Development Centre could be a great fit. Could you point me to the right person to talk to about trips for the girls teams? One of our partner clubs in Ireland won their first ever league title after a few years with us, so I'd be glad to share how it went for them. Thanks a lot, Joel Martinez Founder, Always Up joel.martinez@alwaysup.es | +1 (814) 329 1929 | alwaysup.es | O8: Llamar o contactar vía redes sociales del club para conseguir email directo | P8: 1er email: NADA adjunto, solo texto (firma de texto plano). Si responde con interés: ficha Always-Up-Team-Experience.pdf. Antes de la llamada: deck de empresa (pendiente de crear), solo si hace falta. Tras la llamada: propuesta escrita.
A9: Whitehaven AFC (Juniors Girls U13-U15) | B9: Reino Unido | C9: U13-U15 chicas | D9: Participante confirmado Costa Daurada Cup 2026 + tiene estructura de chicas U13/U14/U15 activa (The FA Full-Time) | E9: costadauradacup.com / fulltime.thefa.com | F9: Luke Johnston (Chairman) | G9: Luke.johnston@whitehavenafc.com | I9: Listo para enviar | J9: Enviar el 15/10/2026 a las 07:30 hora Nueva York. Textos en la hoja 'Textos para copiar'. | K9: A week in Spain for Whitehaven's girls teams | L9: Hi Luke, I'm Joel, I run Always Up. We take youth teams to Spain for a week of training at Atlético de Madrid and Real Sociedad facilities, with matches against local academy sides, a stadium tour, and accommodation and meals all sorted. I saw Whitehaven was down for the Costa Daurada Cup this summer, and that the club has girls teams from under 9 up to under 16, so I thought this could be a good fit. Would you be up for a quick call next week, or would you like a short overview first? And if you're not the right person, could you point me to whoever organises trips for the girls section? Best, Joel Martinez Founder, Always Up joel.martinez@alwaysup.es | +1 (814) 329 1929 | alwaysup.es | O9: Email de Luke Johnston (presidente) sacado de buscadores; la web no lo muestra. Si rebota: Facebook o teléfono +44 1946 692211. | P9: 1er email: NADA adjunto, solo texto (firma de texto plano). Si responde con interés: ficha Always-Up-Team-Experience.pdf. Antes de la llamada: deck de empresa (pendiente de crear), solo si hace falta. Tras la llamada: propuesta escrita.
A10: Lower Ormond | B10: Reino Unido (sin confirmar) | C10: Sin confirmar | D10: Aparecía como participante Costa Daurada Cup 2026 en el research original de julio | E10: costadauradacup.com | I10: Sin identificar con certeza | J10: Verificar directamente en costadauradacup.com — la búsqueda de hoy solo encontró clubes de Ormond en Australia (deporte distinto, AFL), no coincide | O10: Investigado 2026-08-29: posible error de nombre en el research original — no gastar más tiempo hasta verificar en la fuente original | 13/10/2026: costadauradacup.com lo lista como club de Inglaterra en la edición de Semana Santa 2026. Existe: falta encontrar su contacto. | 13/10/2026: aparece como club de Inglaterra en la edición de Semana Santa de la Costa Daurada Cup. No encuentro contacto fiable. | 13/10/2026: aparece como club de Inglaterra en la edición de Semana Santa de la Costa Daurada Cup. No encuentro contacto fiable. | 13/10/2026: aparece como club de Inglaterra en la edición de Semana Santa de la Costa Daurada Cup. No encuentro contacto fiable. | 13/10/2026: aparece como club de Inglaterra en la edición de Semana Santa de la Costa Daurada Cup. No encuentro contacto fiable. | 13/10/2026: aparece como club de Inglaterra en la edición de Semana Santa de la Costa Daurada Cup. No encuentro contacto fiable. | 13/10/2026: aparece como club de Inglaterra en la edición de Semana Santa de la Costa Daurada Cup. No encuentro contacto fiable. | P10: 1er email: NADA adjunto, solo texto (firma de texto plano). Si responde con interés: ficha Always-Up-Team-Experience.pdf. Antes de la llamada: deck de empresa (pendiente de crear), solo si hace falta. Tras la llamada: propuesta escrita.
